<?xml version="1.0" encoding="utf-8"?>
<!-- =================================================================================== -->
<!-- |    This document was autogenerated by xacro from final_drone.xacro              | -->
<!-- |    EDITING THIS FILE BY HAND IS NOT RECOMMENDED                                 | -->
<!-- =================================================================================== -->
<robot name="final_drone">
  <!-- [m] -->
  <!--xacro:include filename="/home/ethan/catkin_ws/src/final_drone/models/final_drone/main_body.xacro" /-->
  <link name="base_link"/>
  <joint name="base_joint" type="fixed">
    <origin rpy="0 0 0" xyz="0 0 0"/>
    <parent link="base_link"/>
    <child link="base_link_inertia"/>
  </joint>
  <link name="base_link_inertia">
    <inertial>
      <mass value="1.5"/>
      <!-- [kg] -->
      <origin xyz="0 0 0"/>
      <inertia ixx="0.003125" ixy="0.0" ixz="0.0" iyy="0.003125" iyz="0.0" izz="0.005625"/>
    </inertial>
    <visual>
      <origin rpy="0 0 0" xyz="0 0 0"/>
      <geometry>
        <!--xacro:include filename="$(arg final_drone_dir)/models/final_drone/main_body.xacro" /-->
        <!--mesh filename="package://rotors_description/meshes/${mesh_file}"
           scale="${mesh_scale}" /-->
        <!--mesh filename="package://final_drone/meshes/main_body_part.STL"
           scale="${mesh_scale}" /-->
        <mesh filename="/home/ethan/catkin_ws/src/final_drone/models/final_drone/meshes/main_body_part.STL" scale="1 1 1"/>
        <!-- <box size="${body_width} ${body_width} ${body_height}"/> -->
        <!-- [m] [m] [m] -->
      </geometry>
    </visual>
    <collision>
      <origin rpy="0 0 0" xyz="0 0 0"/>
      <geometry>
        <box size="0.37 0.15 0.05"/>
        <!-- [m] [m] [m] -->
      </geometry>
    </collision>
  </link>
  <!-- attach multirotor_base_plugin to the base_link -->
  <gazebo>
    <plugin filename="libgazebo_multirotor_base_plugin.so" name="rosbag">
      <robotNamespace>drone</robotNamespace>
      <linkName>base_link</linkName>
      <rotorVelocitySlowdownSim>10</rotorVelocitySlowdownSim>
    </plugin>
  </gazebo>
  <gazebo reference="base_link">
    <material>Gazebo/black</material>
    <collision name="base_link_inertia_collision">
      <surface>
        <contact>
          <ode>
            <min_depth>0.001</min_depth>
            <max_vel>0.0</max_vel>
          </ode>
        </contact>
        <friction>
          <ode/>
        </friction>
      </surface>
    </collision>
  </gazebo>
  <joint name="arm_0" type="continuous">
    <origin rpy="0 0 0" xyz="0.185 0 0.1"/>
    <axis xyz="0 0 1"/>
    <parent link="base_link"/>
    <child link="arm_0"/>
    <dynamics damping="0.3"/>
  </joint>
  <link name="arm_0">
    <mu1>0.5</mu1>
    <mu2>0.5</mu2>
    <inertial>
      <mass value="0.3"/>
      <!-- [kg] -->
      <inertia ixx="0.000125" ixy="0.0" ixz="0.0" iyy="0.000125" iyz="0.0" izz="0.000125"/>
    </inertial>
    <visual>
      <geometry>
        <!--mesh filename="package://final_drone/meshes/rotor_arm_part.STL"
           scale="${mesh_scale}" /-->
        <mesh filename="/home/ethan/catkin_ws/src/final_drone/models/final_drone/meshes/rotor_arm_part_front.STL" scale="1 1 1"/>
      </geometry>
    </visual>
    <collision>
      <geometry>
        <box size="0.05 0.203 0.05"/>
        <!-- [m] [m] [m] -->
      </geometry>
    </collision>
  </link>
  <gazebo reference="arm_0">
    <material>Gazebo/Blue</material>
  </gazebo>
  <joint name="arm_1" type="continuous">
    <origin rpy="0 0 0" xyz="-0.185 0 0.1"/>
    <axis xyz="0 0 1"/>
    <parent link="base_link"/>
    <child link="arm_1"/>
    <dynamics damping="0.3"/>
  </joint>
  <link name="arm_1">
    <mu1>0.5</mu1>
    <mu2>0.5</mu2>
    <inertial>
      <mass value="0.3"/>
      <!-- [kg] -->
      <inertia ixx="0.000125" ixy="0.0" ixz="0.0" iyy="0.000125" iyz="0.0" izz="0.000125"/>
    </inertial>
    <visual>
      <geometry>
        <!--mesh filename="package://final_drone/meshes/rotor_arm_part.STL"
           scale="${mesh_scale}" /-->
        <mesh filename="/home/ethan/catkin_ws/src/final_drone/models/final_drone/meshes/rotor_arm_part_back.STL" scale="1 1 1"/>
      </geometry>
    </visual>
    <collision>
      <geometry>
        <box size="0.05 0.203 0.05"/>
        <!-- [m] [m] [m] -->
      </geometry>
    </collision>
  </link>
  <gazebo reference="arm_1">
    <material>Gazebo/Blue</material>
  </gazebo>
  <joint name="stand_front" type="fixed">
    <origin rpy="0 0 0" xyz="0 0 -0.02"/>
    <axis xyz="0 0 1"/>
    <parent link="arm_0"/>
    <child link="stand_front"/>
  </joint>
  <link name="stand_front">
    <inertial>
      <mass value="0.3"/>
      <!-- [kg] -->
      <inertia ixx="0.0031025" ixy="0.0" ixz="0.0" iyy="0.0031025" iyz="0.0" izz="0.002"/>
    </inertial>
    <visual>
      <geometry>
        <!--mesh filename="package://final_drone/meshes/rotor_arm_part.STL"
           scale="${mesh_scale}" /-->
        <mesh filename="/home/ethan/catkin_ws/src/final_drone/models/final_drone/meshes/stand_front.stl" scale="1 1 1"/>
      </geometry>
    </visual>
    <collision>
      <geometry>
        <box size="0.2 0.13 0.29"/>
        <!-- [m] [m] [m] -->
      </geometry>
    </collision>
  </link>
  <gazebo reference="stand_front">
    <material>Gazebo/white</material>
  </gazebo>
  <joint name="stand_back" type="fixed">
    <origin rpy="0 0 0" xyz="0 0 -0.02"/>
    <axis xyz="0 0 1"/>
    <parent link="arm_1"/>
    <child link="stand_back"/>
  </joint>
  <link name="stand_back">
    <inertial>
      <mass value="0.3"/>
      <!-- [kg] -->
      <inertia ixx="0.0031025" ixy="0.0" ixz="0.0" iyy="0.0031025" iyz="0.0" izz="0.002"/>
    </inertial>
    <visual>
      <geometry>
        <!--mesh filename="package://final_drone/meshes/rotor_arm_part.STL"
           scale="${mesh_scale}" /-->
        <mesh filename="/home/ethan/catkin_ws/src/final_drone/models/final_drone/meshes/stand_back.stl" scale="1 1 1"/>
      </geometry>
    </visual>
    <collision>
      <geometry>
        <box size="0.2 0.13 0.29"/>
        <!-- [m] [m] [m] -->
      </geometry>
    </collision>
  </link>
  <gazebo reference="stand_back">
    <material>Gazebo/white</material>
  </gazebo>
  <joint name="rotor_0_joint" type="continuous">
    <origin rpy="0 0 0" xyz="0 -0.085 0.072"/>
    <axis xyz="0 0 1"/>
    <!-- TODO(ff): not currently set because it's not yet supported -->
    <!-- <limit effort="2000" velocity="${max_rot_velocity}" /> -->
    <parent link="arm_0"/>
    <child link="rotor_0"/>
  </joint>
  <!-- TODO(ff): not currently set because it's not yet supported -->
  <!-- <gazebo reference="rotor_${motor_number}_joint"> <axis> <xyz>0 0 1</xyz>
      <limit> <velocity> ${max_rot_velocity} </velocity> </limit> </axis> </gazebo> -->
  <link name="rotor_0">
    <inertial>
      <mass value="0.005"/>
      <!-- [kg] -->
      <inertia ixx="9.75e-07" ixy="0.0" ixz="0.0" iyy="9.68115e-05" iyz="0.0" izz="9.77115e-05"/>
    </inertial>
    <visual>
      <geometry>
        <!-- <cylinder length="0.005" radius="${radius_rotor}"/> -->
        <!-- [m] -->
        <!-- mesh filename="package://final_drone/meshes/${mesh}_${direction}.dae"-->
        <mesh filename="/home/ethan/catkin_ws/src/final_drone/models/final_drone/meshes/rotor_spinner.STL" scale="1 1 1"/>
        <!-- <box size="${2*radius_rotor} 0.01 0.005"/> -->
      </geometry>
    </visual>
    <collision>
      <geometry>
        <cylinder length="0.005" radius="0.0762"/>
        <!-- [m] -->
      </geometry>
    </collision>
  </link>
  <gazebo>
    <plugin filename="libgazebo_motor_model_gdp2020.so" name="front_right_motor_model">
      <!-- Amended to use the GDP2020_ADD motor plugin. -Tai Ming- -->
      <robotNamespace>drone</robotNamespace>
      <jointName>rotor_0_joint</jointName>
      <linkName>rotor_0</linkName>
      <turningDirection>ccw</turningDirection>
      <timeConstantUp>0.0125</timeConstantUp>
      <timeConstantDown>0.025</timeConstantDown>
      <maxRotVelocity>1100</maxRotVelocity>
      <motorConstant>8.54858e-06</motorConstant>
      <momentConstant>0.06</momentConstant>
      <commandSubTopic>/gazebo/command/motor_speed</commandSubTopic>
      <motorNumber>0</motorNumber>
      <rotorDragCoefficient>0.000806428</rotorDragCoefficient>
      <rollingMomentCoefficient>1e-06</rollingMomentCoefficient>
      <motorSpeedPubTopic>/motor_speed/0</motorSpeedPubTopic>
      <rotorVelocitySlowdownSim>10</rotorVelocitySlowdownSim>
      <!--
        <gazebo_joint_control_pid>
          <p>0.1</p>
          <i>0</i>
          <d>0</d>
          <iMax>0</iMax>
          <iMin>0</iMin>
          <cmdMax>3</cmdMax>
          <cmdMin>-3</cmdMin>
        </gazebo_joint_control_pid>
      -->
    </plugin>
  </gazebo>
  <gazebo reference="rotor_0">
    <material>Gazebo/Red</material>
  </gazebo>
  <joint name="rotor_1_joint" type="continuous">
    <origin rpy="0 0 0" xyz="0 0.085 0.072"/>
    <axis xyz="0 0 1"/>
    <!-- TODO(ff): not currently set because it's not yet supported -->
    <!-- <limit effort="2000" velocity="${max_rot_velocity}" /> -->
    <parent link="arm_1"/>
    <child link="rotor_1"/>
  </joint>
  <!-- TODO(ff): not currently set because it's not yet supported -->
  <!-- <gazebo reference="rotor_${motor_number}_joint"> <axis> <xyz>0 0 1</xyz>
      <limit> <velocity> ${max_rot_velocity} </velocity> </limit> </axis> </gazebo> -->
  <link name="rotor_1">
    <inertial>
      <mass value="0.005"/>
      <!-- [kg] -->
      <inertia ixx="9.75e-07" ixy="0.0" ixz="0.0" iyy="9.68115e-05" iyz="0.0" izz="9.77115e-05"/>
    </inertial>
    <visual>
      <geometry>
        <!-- <cylinder length="0.005" radius="${radius_rotor}"/> -->
        <!-- [m] -->
        <!-- mesh filename="package://final_drone/meshes/${mesh}_${direction}.dae"-->
        <mesh filename="/home/ethan/catkin_ws/src/final_drone/models/final_drone/meshes/rotor_spinner.STL" scale="1 1 1"/>
        <!-- <box size="${2*radius_rotor} 0.01 0.005"/> -->
      </geometry>
    </visual>
    <collision>
      <geometry>
        <cylinder length="0.005" radius="0.0762"/>
        <!-- [m] -->
      </geometry>
    </collision>
  </link>
  <gazebo>
    <plugin filename="libgazebo_motor_model_gdp2020.so" name="back_left_motor_model">
      <!-- Amended to use the GDP2020_ADD motor plugin. -Tai Ming- -->
      <robotNamespace>drone</robotNamespace>
      <jointName>rotor_1_joint</jointName>
      <linkName>rotor_1</linkName>
      <turningDirection>ccw</turningDirection>
      <timeConstantUp>0.0125</timeConstantUp>
      <timeConstantDown>0.025</timeConstantDown>
      <maxRotVelocity>1100</maxRotVelocity>
      <motorConstant>8.54858e-06</motorConstant>
      <momentConstant>0.06</momentConstant>
      <commandSubTopic>/gazebo/command/motor_speed</commandSubTopic>
      <motorNumber>1</motorNumber>
      <rotorDragCoefficient>0.000806428</rotorDragCoefficient>
      <rollingMomentCoefficient>1e-06</rollingMomentCoefficient>
      <motorSpeedPubTopic>/motor_speed/1</motorSpeedPubTopic>
      <rotorVelocitySlowdownSim>10</rotorVelocitySlowdownSim>
      <!--
        <gazebo_joint_control_pid>
          <p>0.1</p>
          <i>0</i>
          <d>0</d>
          <iMax>0</iMax>
          <iMin>0</iMin>
          <cmdMax>3</cmdMax>
          <cmdMin>-3</cmdMin>
        </gazebo_joint_control_pid>
      -->
    </plugin>
  </gazebo>
  <gazebo reference="rotor_1">
    <material>Gazebo/DarkGrey</material>
  </gazebo>
  <joint name="rotor_2_joint" type="continuous">
    <origin rpy="0 0 0" xyz="0 0.085 0.072"/>
    <axis xyz="0 0 1"/>
    <!-- TODO(ff): not currently set because it's not yet supported -->
    <!-- <limit effort="2000" velocity="${max_rot_velocity}" /> -->
    <parent link="arm_0"/>
    <child link="rotor_2"/>
  </joint>
  <!-- TODO(ff): not currently set because it's not yet supported -->
  <!-- <gazebo reference="rotor_${motor_number}_joint"> <axis> <xyz>0 0 1</xyz>
      <limit> <velocity> ${max_rot_velocity} </velocity> </limit> </axis> </gazebo> -->
  <link name="rotor_2">
    <inertial>
      <mass value="0.005"/>
      <!-- [kg] -->
      <inertia ixx="9.75e-07" ixy="0.0" ixz="0.0" iyy="9.68115e-05" iyz="0.0" izz="9.77115e-05"/>
    </inertial>
    <visual>
      <geometry>
        <!-- <cylinder length="0.005" radius="${radius_rotor}"/> -->
        <!-- [m] -->
        <!-- mesh filename="package://final_drone/meshes/${mesh}_${direction}.dae"-->
        <mesh filename="/home/ethan/catkin_ws/src/final_drone/models/final_drone/meshes/rotor_spinner.STL" scale="1 1 1"/>
        <!-- <box size="${2*radius_rotor} 0.01 0.005"/> -->
      </geometry>
    </visual>
    <collision>
      <geometry>
        <cylinder length="0.005" radius="0.0762"/>
        <!-- [m] -->
      </geometry>
    </collision>
  </link>
  <gazebo>
    <plugin filename="libgazebo_motor_model_gdp2020.so" name="front_left_motor_model">
      <!-- Amended to use the GDP2020_ADD motor plugin. -Tai Ming- -->
      <robotNamespace>drone</robotNamespace>
      <jointName>rotor_2_joint</jointName>
      <linkName>rotor_2</linkName>
      <turningDirection>cw</turningDirection>
      <timeConstantUp>0.0125</timeConstantUp>
      <timeConstantDown>0.025</timeConstantDown>
      <maxRotVelocity>1100</maxRotVelocity>
      <motorConstant>8.54858e-06</motorConstant>
      <momentConstant>0.06</momentConstant>
      <commandSubTopic>/gazebo/command/motor_speed</commandSubTopic>
      <motorNumber>2</motorNumber>
      <rotorDragCoefficient>0.000806428</rotorDragCoefficient>
      <rollingMomentCoefficient>1e-06</rollingMomentCoefficient>
      <motorSpeedPubTopic>/motor_speed/2</motorSpeedPubTopic>
      <rotorVelocitySlowdownSim>10</rotorVelocitySlowdownSim>
      <!--
        <gazebo_joint_control_pid>
          <p>0.1</p>
          <i>0</i>
          <d>0</d>
          <iMax>0</iMax>
          <iMin>0</iMin>
          <cmdMax>3</cmdMax>
          <cmdMin>-3</cmdMin>
        </gazebo_joint_control_pid>
      -->
    </plugin>
  </gazebo>
  <gazebo reference="rotor_2">
    <material>Gazebo/Red</material>
  </gazebo>
  <joint name="rotor_3_joint" type="continuous">
    <origin rpy="0 0 0" xyz="0 -0.085 0.072"/>
    <axis xyz="0 0 1"/>
    <!-- TODO(ff): not currently set because it's not yet supported -->
    <!-- <limit effort="2000" velocity="${max_rot_velocity}" /> -->
    <parent link="arm_1"/>
    <child link="rotor_3"/>
  </joint>
  <!-- TODO(ff): not currently set because it's not yet supported -->
  <!-- <gazebo reference="rotor_${motor_number}_joint"> <axis> <xyz>0 0 1</xyz>
      <limit> <velocity> ${max_rot_velocity} </velocity> </limit> </axis> </gazebo> -->
  <link name="rotor_3">
    <inertial>
      <mass value="0.005"/>
      <!-- [kg] -->
      <inertia ixx="9.75e-07" ixy="0.0" ixz="0.0" iyy="9.68115e-05" iyz="0.0" izz="9.77115e-05"/>
    </inertial>
    <visual>
      <geometry>
        <!-- <cylinder length="0.005" radius="${radius_rotor}"/> -->
        <!-- [m] -->
        <!-- mesh filename="package://final_drone/meshes/${mesh}_${direction}.dae"-->
        <mesh filename="/home/ethan/catkin_ws/src/final_drone/models/final_drone/meshes/rotor_spinner.STL" scale="1 1 1"/>
        <!-- <box size="${2*radius_rotor} 0.01 0.005"/> -->
      </geometry>
    </visual>
    <collision>
      <geometry>
        <cylinder length="0.005" radius="0.0762"/>
        <!-- [m] -->
      </geometry>
    </collision>
  </link>
  <gazebo>
    <plugin filename="libgazebo_motor_model_gdp2020.so" name="back_right_motor_model">
      <!-- Amended to use the GDP2020_ADD motor plugin. -Tai Ming- -->
      <robotNamespace>drone</robotNamespace>
      <jointName>rotor_3_joint</jointName>
      <linkName>rotor_3</linkName>
      <turningDirection>cw</turningDirection>
      <timeConstantUp>0.0125</timeConstantUp>
      <timeConstantDown>0.025</timeConstantDown>
      <maxRotVelocity>1100</maxRotVelocity>
      <motorConstant>8.54858e-06</motorConstant>
      <momentConstant>0.06</momentConstant>
      <commandSubTopic>/gazebo/command/motor_speed</commandSubTopic>
      <motorNumber>3</motorNumber>
      <rotorDragCoefficient>0.000806428</rotorDragCoefficient>
      <rollingMomentCoefficient>1e-06</rollingMomentCoefficient>
      <motorSpeedPubTopic>/motor_speed/3</motorSpeedPubTopic>
      <rotorVelocitySlowdownSim>10</rotorVelocitySlowdownSim>
      <!--
        <gazebo_joint_control_pid>
          <p>0.1</p>
          <i>0</i>
          <d>0</d>
          <iMax>0</iMax>
          <iMin>0</iMin>
          <cmdMax>3</cmdMax>
          <cmdMin>-3</cmdMin>
        </gazebo_joint_control_pid>
      -->
    </plugin>
  </gazebo>
  <gazebo reference="rotor_3">
    <material>Gazebo/DarkGrey</material>
  </gazebo>
  <!-- add joint ROS control-->
  <gazebo>
    <plugin filename="libgazebo_ros_control.so" name="gazebo_ros_control">
      <robotNamespace>drone</robotNamespace>
    </plugin>
  </gazebo>
  <transmission name="tran_0">
    <type>transmission_interface/SimpleTransmission</type>
    <joint name="arm_0">
      <hardwareInterface>hardware_interface/EffortJointInterface</hardwareInterface>
    </joint>
    <actuator name="servo_0">
      <hardwareInterface>hardware_interface/EffortJointInterface</hardwareInterface>
      <mechanicalReduction>1</mechanicalReduction>
    </actuator>
  </transmission>
  <transmission name="tran_1">
    <type>transmission_interface/SimpleTransmission</type>
    <joint name="arm_1">
      <hardwareInterface>hardware_interface/EffortJointInterface</hardwareInterface>
    </joint>
    <actuator name="servo_1">
      <hardwareInterface>hardware_interface/EffortJointInterface</hardwareInterface>
      <mechanicalReduction>1</mechanicalReduction>
    </actuator>
  </transmission>
</robot>

